[2024-04-17 16:40:16,488] INFO _log() L224  127.0.0.1 - - [17/Apr/2024 16:40:16] "PUT /cliente HTTP/1.1" 200 - - call_trace=C:\Users\F_Mota\AppData\Roaming\Python\Python310\site-packages\werkzeug\_internal.py L224 
[2024-04-17 16:40:30,989] WARNING update_cliente() L95   Erro ao adicionar cliente '523452477744555', Cliente de mesmo nome já salvo na base :/ - call_trace=C:\Users\F_Mota\Downloads\aula_3_V2\aula-3\meu_app_api\app.py L95  
[2024-04-17 16:40:30,990] INFO _log() L224  127.0.0.1 - - [17/Apr/2024 16:40:30] "[31m[1mPUT /cliente HTTP/1.1[0m" 409 - - call_trace=C:\Users\F_Mota\AppData\Roaming\Python\Python310\site-packages\werkzeug\_internal.py L224 
[2024-04-17 16:41:13,316] INFO _log() L224  127.0.0.1 - - [17/Apr/2024 16:41:13] "PUT /cliente HTTP/1.1" 200 - - call_trace=C:\Users\F_Mota\AppData\Roaming\Python\Python310\site-packages\werkzeug\_internal.py L224 
[2024-04-17 16:41:20,463] INFO _log() L224  127.0.0.1 - - [17/Apr/2024 16:41:20] "GET /openapi/swagger HTTP/1.1" 200 - - call_trace=C:\Users\F_Mota\AppData\Roaming\Python\Python310\site-packages\werkzeug\_internal.py L224 
[2024-04-17 16:41:20,491] INFO _log() L224  127.0.0.1 - - [17/Apr/2024 16:41:20] "[36mGET /openapi/static/css/swagger-ui.css HTTP/1.1[0m" 304 - - call_trace=C:\Users\F_Mota\AppData\Roaming\Python\Python310\site-packages\werkzeug\_internal.py L224 
[2024-04-17 16:41:20,501] INFO _log() L224  127.0.0.1 - - [17/Apr/2024 16:41:20] "[36mGET /openapi/static/js/swagger-ui-bundle.js HTTP/1.1[0m" 304 - - call_trace=C:\Users\F_Mota\AppData\Roaming\Python\Python310\site-packages\werkzeug\_internal.py L224 
[2024-04-17 16:41:20,502] INFO _log() L224  127.0.0.1 - - [17/Apr/2024 16:41:20] "[36mGET /openapi/static/js/swagger-ui-standalone-preset.js HTTP/1.1[0m" 304 - - call_trace=C:\Users\F_Mota\AppData\Roaming\Python\Python310\site-packages\werkzeug\_internal.py L224 
[2024-04-17 16:41:20,517] INFO _log() L224  127.0.0.1 - - [17/Apr/2024 16:41:20] "[33mGET /openapi/static/css/swagger-ui.css.map HTTP/1.1[0m" 404 - - call_trace=C:\Users\F_Mota\AppData\Roaming\Python\Python310\site-packages\werkzeug\_internal.py L224 
[2024-04-17 16:41:20,628] INFO _log() L224  127.0.0.1 - - [17/Apr/2024 16:41:20] "[33mGET /openapi/static/js/swagger-ui-bundle.js.map HTTP/1.1[0m" 404 - - call_trace=C:\Users\F_Mota\AppData\Roaming\Python\Python310\site-packages\werkzeug\_internal.py L224 
[2024-04-17 16:41:20,680] INFO _log() L224  127.0.0.1 - - [17/Apr/2024 16:41:20] "[33mGET /openapi/static/js/swagger-ui-standalone-preset.js.map HTTP/1.1[0m" 404 - - call_trace=C:\Users\F_Mota\AppData\Roaming\Python\Python310\site-packages\werkzeug\_internal.py L224 
[2024-04-17 16:41:20,738] INFO _log() L224  127.0.0.1 - - [17/Apr/2024 16:41:20] "GET /openapi/openapi.json HTTP/1.1" 200 - - call_trace=C:\Users\F_Mota\AppData\Roaming\Python\Python310\site-packages\werkzeug\_internal.py L224 
[2024-04-17 16:41:20,747] INFO _log() L224  127.0.0.1 - - [17/Apr/2024 16:41:20] "[36mGET /openapi/static/images/swagger.svg HTTP/1.1[0m" 304 - - call_trace=C:\Users\F_Mota\AppData\Roaming\Python\Python310\site-packages\werkzeug\_internal.py L224 
[2024-04-17 16:41:37,815] WARNING update_cliente() L101  Erro ao adicionar cliente 'Renato Lisboa da Silva', 'NoneType' object has no attribute 'nome' - call_trace=C:\Users\F_Mota\Downloads\aula_3_V2\aula-3\meu_app_api\app.py L101 
[2024-04-17 16:41:37,816] ERROR log_exception() L1449 Exception on /cliente [PUT] - call_trace=C:\Users\F_Mota\AppData\Roaming\Python\Python310\site-packages\flask\app.py L1449
Traceback (most recent call last):
  File "C:\Users\F_Mota\AppData\Roaming\Python\Python310\site-packages\flask\app.py", line 2073, in wsgi_app
    response = self.full_dispatch_request()
  File "C:\Users\F_Mota\AppData\Roaming\Python\Python310\site-packages\flask\app.py", line 1520, in full_dispatch_request
    return self.finalize_request(rv)
  File "C:\Users\F_Mota\AppData\Roaming\Python\Python310\site-packages\flask\app.py", line 1539, in finalize_request
    response = self.make_response(rv)
  File "C:\Users\F_Mota\AppData\Roaming\Python\Python310\site-packages\flask\app.py", line 1714, in make_response
    rv = jsonify(rv)
  File "C:\Users\F_Mota\AppData\Roaming\Python\Python310\site-packages\flask\json\__init__.py", line 302, in jsonify
    f"{dumps(data, indent=indent, separators=separators)}\n",
  File "C:\Users\F_Mota\AppData\Roaming\Python\Python310\site-packages\flask\json\__init__.py", line 132, in dumps
    return _json.dumps(obj, **kwargs)
  File "C:\Program Files\Python310\lib\json\__init__.py", line 238, in dumps
    **kw).encode(obj)
  File "C:\Program Files\Python310\lib\json\encoder.py", line 199, in encode
    chunks = self.iterencode(o, _one_shot=True)
  File "C:\Program Files\Python310\lib\json\encoder.py", line 257, in iterencode
    return _iterencode(o, 0)
  File "C:\Users\F_Mota\AppData\Roaming\Python\Python310\site-packages\flask\json\__init__.py", line 51, in default
    return super().default(o)
  File "C:\Program Files\Python310\lib\json\encoder.py", line 179, in default
    raise TypeError(f'Object of type {o.__class__.__name__} '
TypeError: Object of type AttributeError is not JSON serializable
[2024-04-17 16:41:37,821] INFO _log() L224  127.0.0.1 - - [17/Apr/2024 16:41:37] "[35m[1mPUT /cliente HTTP/1.1[0m" 500 - - call_trace=C:\Users\F_Mota\AppData\Roaming\Python\Python310\site-packages\werkzeug\_internal.py L224 
[2024-04-17 16:41:43,423] WARNING update_cliente() L101  Erro ao adicionar cliente 'Renato Lisboa da Silva5', 'NoneType' object has no attribute 'nome' - call_trace=C:\Users\F_Mota\Downloads\aula_3_V2\aula-3\meu_app_api\app.py L101 
[2024-04-17 16:41:43,424] ERROR log_exception() L1449 Exception on /cliente [PUT] - call_trace=C:\Users\F_Mota\AppData\Roaming\Python\Python310\site-packages\flask\app.py L1449
Traceback (most recent call last):
  File "C:\Users\F_Mota\AppData\Roaming\Python\Python310\site-packages\flask\app.py", line 2073, in wsgi_app
    response = self.full_dispatch_request()
  File "C:\Users\F_Mota\AppData\Roaming\Python\Python310\site-packages\flask\app.py", line 1520, in full_dispatch_request
    return self.finalize_request(rv)
  File "C:\Users\F_Mota\AppData\Roaming\Python\Python310\site-packages\flask\app.py", line 1539, in finalize_request
    response = self.make_response(rv)
  File "C:\Users\F_Mota\AppData\Roaming\Python\Python310\site-packages\flask\app.py", line 1714, in make_response
    rv = jsonify(rv)
  File "C:\Users\F_Mota\AppData\Roaming\Python\Python310\site-packages\flask\json\__init__.py", line 302, in jsonify
    f"{dumps(data, indent=indent, separators=separators)}\n",
  File "C:\Users\F_Mota\AppData\Roaming\Python\Python310\site-packages\flask\json\__init__.py", line 132, in dumps
    return _json.dumps(obj, **kwargs)
  File "C:\Program Files\Python310\lib\json\__init__.py", line 238, in dumps
    **kw).encode(obj)
  File "C:\Program Files\Python310\lib\json\encoder.py", line 199, in encode
    chunks = self.iterencode(o, _one_shot=True)
  File "C:\Program Files\Python310\lib\json\encoder.py", line 257, in iterencode
    return _iterencode(o, 0)
  File "C:\Users\F_Mota\AppData\Roaming\Python\Python310\site-packages\flask\json\__init__.py", line 51, in default
    return super().default(o)
  File "C:\Program Files\Python310\lib\json\encoder.py", line 179, in default
    raise TypeError(f'Object of type {o.__class__.__name__} '
TypeError: Object of type AttributeError is not JSON serializable
[2024-04-17 16:41:43,427] INFO _log() L224  127.0.0.1 - - [17/Apr/2024 16:41:43] "[35m[1mPUT /cliente HTTP/1.1[0m" 500 - - call_trace=C:\Users\F_Mota\AppData\Roaming\Python\Python310\site-packages\werkzeug\_internal.py L224 
[2024-04-17 16:41:47,185] WARNING update_cliente() L101  Erro ao adicionar cliente 'Renato Lisboa da Silva5', 'NoneType' object has no attribute 'nome' - call_trace=C:\Users\F_Mota\Downloads\aula_3_V2\aula-3\meu_app_api\app.py L101 
[2024-04-17 16:41:47,185] ERROR log_exception() L1449 Exception on /cliente [PUT] - call_trace=C:\Users\F_Mota\AppData\Roaming\Python\Python310\site-packages\flask\app.py L1449
Traceback (most recent call last):
  File "C:\Users\F_Mota\AppData\Roaming\Python\Python310\site-packages\flask\app.py", line 2073, in wsgi_app
    response = self.full_dispatch_request()
  File "C:\Users\F_Mota\AppData\Roaming\Python\Python310\site-packages\flask\app.py", line 1520, in full_dispatch_request
    return self.finalize_request(rv)
  File "C:\Users\F_Mota\AppData\Roaming\Python\Python310\site-packages\flask\app.py", line 1539, in finalize_request
    response = self.make_response(rv)
  File "C:\Users\F_Mota\AppData\Roaming\Python\Python310\site-packages\flask\app.py", line 1714, in make_response
    rv = jsonify(rv)
  File "C:\Users\F_Mota\AppData\Roaming\Python\Python310\site-packages\flask\json\__init__.py", line 302, in jsonify
    f"{dumps(data, indent=indent, separators=separators)}\n",
  File "C:\Users\F_Mota\AppData\Roaming\Python\Python310\site-packages\flask\json\__init__.py", line 132, in dumps
    return _json.dumps(obj, **kwargs)
  File "C:\Program Files\Python310\lib\json\__init__.py", line 238, in dumps
    **kw).encode(obj)
  File "C:\Program Files\Python310\lib\json\encoder.py", line 199, in encode
    chunks = self.iterencode(o, _one_shot=True)
  File "C:\Program Files\Python310\lib\json\encoder.py", line 257, in iterencode
    return _iterencode(o, 0)
  File "C:\Users\F_Mota\AppData\Roaming\Python\Python310\site-packages\flask\json\__init__.py", line 51, in default
    return super().default(o)
  File "C:\Program Files\Python310\lib\json\encoder.py", line 179, in default
    raise TypeError(f'Object of type {o.__class__.__name__} '
TypeError: Object of type AttributeError is not JSON serializable
